<?xml version="1.0" ?>
<!-- =================================================================================== -->
<!-- |    This document was autogenerated by xacro from /home/luke/dexarm_ws/src/dexarm_description/urdf/dexarm.xacro | -->
<!-- |    EDITING THIS FILE BY HAND IS NOT RECOMMENDED                                 | -->
<!-- =================================================================================== -->
<!-- Revolute-Revolute Manipulator -->
<robot name="dexarm">
  <!-- Link 3 -->
  <!-- ros_control plugin -->
  <!-- <gazebo>
    <plugin filename="libgazebo_ros_control.so" name="gazebo_ros_control">
      <robotNamespace>/dexarm</robotNamespace>
      <robotSimType>gazebo_ros_control/DefaultRobotHWSim</robotSimType>
    </plugin>
  </gazebo>
  <gazebo reference="B_Fix">
    <material>Gazebo/White</material>
  </gazebo>
  <gazebo reference="B_Rot">
    <material>Gazebo/White</material>
  </gazebo>
  <gazebo reference="In_1">
    <material>Gazebo/Black</material>
  </gazebo>
  <gazebo reference="Join">
    <material>Gazebo/White</material>
  </gazebo>
  <gazebo reference="In_2">
    <material>Gazebo/Black</material>
  </gazebo>
  <gazebo reference="EE">
    <material>Gazebo/Black</material>
  </gazebo> -->
  <!-- For simulation  -->
  <joint name="fixed" type="fixed">
    <parent link="world"/>
    <child link="B_Fix"/>
  </joint>
  <link name="B_Fix">
    <visual>
      <origin rpy="0 0 0" xyz="0 0 0"/>
      <geometry>
        <mesh filename="package://dexarm_description/urdf/STL/00-B_Fix.stl" scale="0.001 0.001 0.001"/>
      </geometry>
    </visual>
    <collision>
      <origin rpy="0 0 0" xyz="0 0 0"/>
      <geometry>
        <mesh filename="package://dexarm_description/urdf/STL/00-B_Fix.stl" scale="0.001 0.001 0.001"/>
      </geometry>
    </collision>
    <inertial>
      <origin rpy="0 0 0" xyz="0 0 0"/>
      <mass value="1"/>
      <inertia ixx="0.3341666666666666" ixy="0.0" ixz="0.0" iyy="0.3341666666666666" iyz="0.0" izz="0.001666666666666667"/>
    </inertial>
  </link>
  <joint name="bases" type="revolute">
    <parent link="B_Fix"/>
    <child link="B_Rot"/>
    <limit effort="30" lower="-1.91986" upper="1.91986" velocity="1.74533"/>
    <origin rpy="0 0 0" xyz="0 0 0"/>
    <axis xyz="0 0 1"/>
  </joint>
  <link name="B_Rot">
    <visual>
      <origin rpy="0 0 0" xyz="0 0 0"/>
      <geometry>
        <mesh filename="package://dexarm_description/urdf/STL/01-B_Rot.stl" scale="0.001 0.001 0.001"/>
      </geometry>
    </visual>
    <collision>
      <origin rpy="0 0 0" xyz="0 0 0"/>
      <geometry>
        <mesh filename="package://dexarm_description/urdf/STL/01-B_Rot.stl" scale="0.001 0.001 0.001"/>
      </geometry>
    </collision>
    <inertial>
      <origin rpy="0 0 0" xyz="0 0 0"/>
      <mass value="1"/>
      <inertia ixx="0.3341666666666666" ixy="0.0" ixz="0.0" iyy="0.3341666666666666" iyz="0.0" izz="0.001666666666666667"/>
    </inertial>
  </link>
  <joint name="B_Rot-&gt;In_1" type="revolute">
    <parent link="B_Rot"/>
    <child link="In_1"/>
    <limit effort="30" lower="0" upper="1.57" velocity="1.74533"/>
    <origin rpy="0 0 0" xyz="0 -0.02 0.13"/>
    <axis xyz="1 0 0"/>
  </joint>
  <link name="In_1">
    <visual>
      <origin rpy="0 0 0" xyz="0 0.022 -0.127"/>
      <geometry>
        <mesh filename="package://dexarm_description/urdf/STL/02-In_1.stl" scale="0.001 0.001 0.001"/>
      </geometry>
    </visual>
    <collision>
      <origin rpy="0 0 0" xyz="0 0.022 -0.127"/>
      <geometry>
        <mesh filename="package://dexarm_description/urdf/STL/02-In_1.stl" scale="0.001 0.001 0.001"/>
      </geometry>
    </collision>
    <inertial>
      <origin rpy="0 0 0" xyz="0 0.022 -0.127"/>
      <mass value="1"/>
      <inertia ixx="0.3341666666666666" ixy="0.0" ixz="0.0" iyy="0.3341666666666666" iyz="0.0" izz="0.001666666666666667"/>
    </inertial>
  </link>
  <joint name="In_1-&gt;Join" type="revolute">
    <parent link="In_1"/>
    <child link="Join"/>
    <limit effort="30" lower="-1.57" upper="0" velocity="1.74533"/>
    <origin rpy="0 0 0" xyz="0 -0.0112 0.15"/>
    <axis xyz="1 0 0"/>
    <mimic joint="B_Rot-&gt;In_1" multiplier="-1" offset="0"/>
  </joint>
  <link name="Join">
    <visual>
      <origin rpy="0 0 0" xyz="0 0.0332 -0.277"/>
      <geometry>
        <mesh filename="package://dexarm_description/urdf/STL/03-Join.stl" scale="0.001 0.001 0.001"/>
      </geometry>
    </visual>
    <collision>
      <origin rpy="0 0 0" xyz="0 0.0332 -0.277"/>
      <geometry>
        <mesh filename="package://dexarm_description/urdf/STL/03-Join.stl" scale="0.001 0.001 0.001"/>
      </geometry>
    </collision>
    <inertial>
      <origin rpy="0 0 0" xyz="0 0.0332 -0.277"/>
      <mass value="1"/>
      <inertia ixx="0.3341666666666666" ixy="0.0" ixz="0.0" iyy="0.3341666666666666" iyz="0.0" izz="0.001666666666666667"/>
    </inertial>
  </link>
  <joint name="Join-&gt;In_2" type="revolute">
    <parent link="Join"/>
    <child link="In_2"/>
    <limit effort="30" lower="-0.6" upper="1.2" velocity="1.74533"/>
    <origin rpy="0 0 0" xyz="0.0 -0.0003 -0.0003"/>
    <axis xyz="1 0 0"/>
  </joint>
  <link name="In_2">
    <visual>
      <origin rpy="0 0 0" xyz="0 0.034 -0.276"/>
      <geometry>
        <mesh filename="package://dexarm_description/urdf/STL/04-In_2.stl" scale="0.001 0.001 0.001"/>
      </geometry>
    </visual>
    <collision>
      <origin rpy="0 0 0" xyz="0 0.033 -0.279"/>
      <geometry>
        <mesh filename="package://dexarm_description/urdf/STL/04-In_2.stl" scale="0.001 0.001 0.001"/>
      </geometry>
    </collision>
    <inertial>
      <origin rpy="0 0 0" xyz="0 0.033 -0.279"/>
      <mass value="1"/>
      <inertia ixx="0.3341666666666666" ixy="0.0" ixz="0.0" iyy="0.3341666666666666" iyz="0.0" izz="0.001666666666666667"/>
    </inertial>
  </link>
  <joint name="In_2-&gt;EE" type="revolute">
    <parent link="In_2"/>
    <child link="EE"/>
    <origin rpy="0 0 0" xyz="0 -0.138 -0.058"/>
    <axis xyz="1 0 0"/>
    <limit effort="30" lower="-3.14" upper="3.14" velocity="1.74533"/>
    <mimic joint="Join-&gt;In_2" multiplier="-1" offset="0"/>
  </joint>
  <link name="EE">
    <visual>
      <origin rpy="0 0 0" xyz="0.0 0.172 -0.218"/>
      <geometry>
        <mesh filename="package://dexarm_description/urdf/STL/05-EE.stl" scale="0.001 0.001 0.001"/>
      </geometry>
    </visual>
    <collision>
      <origin rpy="0 0 0" xyz="0.0 0.172 -0.215"/>
      <geometry>
        <mesh filename="package://dexarm_description/urdf/STL/05-EE.stl" scale="0.001 0.001 0.001"/>
      </geometry>
    </collision>
    <inertial>
      <origin rpy="0 0 0" xyz="0.0 0.172 -0.215"/>
      <mass value="1"/>
      <inertia ixx="0.3341666666666666" ixy="0.0" ixz="0.0" iyy="0.3341666666666666" iyz="0.0" izz="0.001666666666666667"/>
    </inertial>
  </link>
</robot>
